<?xml version='1.0'?>
<sdf version='1.4'>
  <world name="default">
    <!-- A global light source -->
    <include>
      <uri>model://sun</uri>
    </include>
    <!-- A ground plane -->
    <include>
      <uri>model://ground_plane</uri>
    </include>
		<model name="arm">
			<static> false </static>
			<link name="Base-bearing-guide">
				<pose> -0.09 -0.065 0  1.57 0 1.57</pose>
				<inertial>
					<pose>0.065 0.004 0.090 0 0 0</pose>
					<mass> 0.15</mass>
					<inertia>
						<ixx>0.000415414</ixx>
						<iyy>0.000625718</iyy>
						<izz>0.000212773</izz>
						<ixy>0</ixy>
						<ixz>0</ixz>
						<iyz>0</iyz>
					</inertia>
				</inertial>				
				<collision name="Base-bearing-guide">
					<geometry>
						<!--cylinder>
							<length> 0.05 </length>
							<radius> 0.2 </radius>
						</cylinder-->
						<mesh>
							<uri>model://parallelogram_arm_robot/meshes/Base-bearing-guide.dae</uri>
							<scale>0.001 0.001 0.001 </scale>
						</mesh>
					</geometry>
				</collision>
			
				<visual name="Base-bearing-guide">
					<geometry>
						<!--cylinder>
							<length> 0.05 </length>
							<radius> 0.2 </radius>
						</cylinder-->
						<mesh>
							<uri>model://parallelogram_arm_robot/meshes/Base-bearing-guide.dae</uri>
							<scale>0.001 0.001 0.001 </scale>
						</mesh>					
					</geometry>
					<material>
						<ambient> 0 0 0.5 .5 </ambient>
					</material>			
				</visual>
			</link>
		
	<!-- ############### joint0 01 ############## -->
			<joint type="revolute" name="joint01">
				<pose>0.05 0 0.05 0 0 0 </pose>
				<child>Base-bearing-holder</child>
				<parent>Base-bearing-guide</parent>			
				<axis>
					<xyz>0 0 1</xyz>
					<limit>
						<upper> 0 </upper>
						<lower> 0 </lower>
					</limit>
				</axis>
			</joint>			
	<!-- #################################################### -->		
			<link name="Base-bearing-holder">
				<pose> -0.05 -0.05 0.02  -1.57 0 0</pose>
				<inertial>
					<pose>0.049 0.005 0.049 0 0 0</pose>
					<mass> 0.042 </mass>
					<inertia>
						<ixx>0.000028</ixx>
						<iyy>0.0000567</iyy>
						<izz>0.0000294</izz>
						<ixy>0</ixy>
						<ixz>0</ixz>
						<iyz>0</iyz>
					</inertia>
				</inertial>			
				<collision name="Base-bearing-holder">
					<geometry>
						<!--cylinder>
							<length> 0.05 </length>
							<radius> 0.2 </radius>
						</cylinder-->
						<mesh>
							<uri>model://parallelogram_arm_robot/meshes/Base-bearingholder.dae</uri>
							<scale>0.001 0.001 0.001 </scale>
						</mesh>
					</geometry>
				</collision>
			
				<visual name="Base-bearing-holder">
					<geometry>
						<!--cylinder>
							<length> 0.05 </length>
							<radius> 0.2 </radius>
						</cylinder-->
						<mesh>
							<uri>model://parallelogram_arm_robot/meshes/Base-bearingholder.dae</uri>
							<scale>0.001 0.001 0.001 </scale>
						</mesh>					
					</geometry>
					<material>
						<ambient> 0 0 0.5 .5 </ambient>
					</material>			
				</visual>
			</link>	
		
	<!-- ############### joint0 01 ############## -->
			<joint type="revolute" name="joint02">
				<pose>0.06 0 0.06 0 0 0 </pose>
				<child>Base-bearing-top</child>
				<parent>Base-bearing-holder</parent>			
				<axis>
					<xyz>0 0 1</xyz>
				</axis>
			</joint>			
	<!-- #################################################### -->			
	<!-- ##################################################-->
			<link name="Base-bearing-top">
				<pose> -0.06 -0.06 0.03  -1.57 0 0</pose>
				<inertial>
					<pose>0.061 0.004 0.060 0 0 0</pose>
					<mass> 0.057 </mass>
					<inertia>
						<ixx>56000e-9</ixx>
						<iyy>108500e-9</iyy>
						<izz>53200e-9</izz>
						<ixy>0</ixy>
						<ixz>0</ixz>
						<iyz>0</iyz>
					</inertia>
				</inertial>			
				<collision name="Base-bearing-top">
					<geometry>
						<!--cylinder>
							<length> 0.05 </length>
							<radius> 0.2 </radius>
						</cylinder-->
						<mesh>
							<uri>model://parallelogram_arm_robot/meshes/Base-bearing-top.dae</uri>
							<scale>0.001 0.001 0.001 </scale>
						</mesh>
					</geometry>
				</collision>
			
				<visual name="Base-bearing-top">
					<geometry>
						<!--cylinder>
							<length> 0.05 </length>
							<radius> 0.2 </radius>
						</cylinder-->
						<mesh>
							<uri>model://parallelogram_arm_robot/meshes/Base-bearing-top.dae</uri>
							<scale>0.001 0.001 0.001 </scale>
						</mesh>					
					</geometry>
					<material>
						<ambient> 0 0 0.5 .5 </ambient>
					</material>			
				</visual>
			</link>	


	<!-- ############### joint0 01 ############## -->
			<joint type="revolute" name="joint11">
				<pose>0.05 0 0 0 0 0 </pose>
				<child>AxesSupport1</child>
				<parent>Base-bearing-top</parent>			
				<axis>
					<xyz>0 0 1</xyz>
					<limit>
						<upper> 0 </upper>
						<lower> 0 </lower>
					</limit>
				</axis>
			</joint>			
	<!-- #################################################### -->		
	<!-- ##################################################-->
			<link name="AxesSupport1">
				<pose> -0.05 -0.015 0.03  1.57 0 0</pose>
				<inertial>
					<pose>0.051 0.043 0.005 0 0 0</pose>
					<mass> 0.051 </mass>
					<inertia>
						<ixx>46676e-9</ixx>
						<iyy>34433e-9</iyy>
						<izz>0.000080249</izz>
						<ixy>-4151e-9</ixy>
						<ixz>0</ixz>
						<iyz>0</iyz>
					</inertia>
				</inertial>		
				<collision name="AxesSupport1">
					<geometry>
						<mesh>
							<uri>model://parallelogram_arm_robot/meshes/AxesSupport1.dae</uri>
							<scale>0.001 0.001 0.001 </scale>
						</mesh>
					</geometry>
				</collision>
			
				<visual name="AxesSupport1">
					<geometry>
						<mesh>
							<uri>model://parallelogram_arm_robot/meshes/AxesSupport1.dae</uri>
							<scale>0.001 0.001 0.001 </scale>
						</mesh>					
					</geometry>
					<material>
						<ambient> 0 0 0.5 .5 </ambient>
					</material>			
				</visual>
			</link>		
		
	<!-- ############### joint0 01 ############## -->
			<joint type="revolute" name="joint12">
				<pose>0.05 0 0.0 0 0 0 </pose>
				<child>AxesSupport2</child>
				<parent>Base-bearing-top</parent>			
				<axis>
					<xyz>0 0 1</xyz>
					<limit>
						<upper> 0 </upper>
						<lower> 0 </lower>
					</limit>
				</axis>
			</joint>			
	<!-- #################################################### -->		
		
	<!-- ##################################################-->
			<link name="AxesSupport2">
				<pose> -0.05 +0.025 0.03  1.57 0 0</pose>
				<inertial>
					<pose>0.051 0.043 0.005 0 0 0</pose>
					<mass> 0.051 </mass>
					<inertia>
						<ixx>46676e-9</ixx>
						<iyy>34433e-9</iyy>
						<izz>0.000080249</izz>
						<ixy>-4151e-9</ixy>
						<ixz>0</ixz>
						<iyz>0</iyz>
					</inertia>
				</inertial>
				<collision name="AxesSupport2">
					<geometry>
						<mesh>
							<uri>model://parallelogram_arm_robot/meshes/AxesSupport2.dae</uri>
							<scale>0.001 0.001 0.001 </scale>
						</mesh>
					</geometry>
				</collision>
			
				<visual name="AxesSupport2">
					<geometry>
						<mesh>
							<uri>model://parallelogram_arm_robot/meshes/AxesSupport2.dae</uri>
							<scale>0.001 0.001 0.001 </scale>
						</mesh>					
					</geometry>
					<material>
						<ambient> 0 0 0.5 .5 </ambient>
					</material>			
				</visual>
			</link>		

	<!-- ############### joint0 01 ############## -->
			<joint type="revolute" name="joint21">
				<pose>0.025 0.025 0.0 0 0 0 </pose>
				<child>Driver-adapter</child>
				<parent>AxesSupport2</parent>			
				<axis>
					<xyz>0 0 1</xyz>
					<limit>
						<upper> 0 </upper>
						<lower> 0 </lower>
					</limit>
				</axis>
			</joint>
		
	<!-- ############### joint0 01 ############## -->
			<joint type="revolute" name="joint22">
				<pose>0.025 0.025 0.0 0 0 0 </pose>
				<child>Driver-adapter2</child>
				<parent>AxesSupport1</parent>			
				<axis>
					<xyz>0 0 1</xyz>
					<limit>
						<upper> 0 </upper>
						<lower> 0 </lower>
					</limit>
				</axis>
			</joint>					
	<!-- #################################################### -->
		
	<!-- ##################################################-->
			<link name="Driver-adapter">
				<pose> 0.025 -0.0125 0.0805  1.57 0 3.14</pose>
				<inertial>
					<pose>0.025 0.025 0.002 0 0 0</pose>
					<mass> 0.006 </mass>
					<inertia>
						<ixx>1064e-9</ixx>
						<iyy>1064e-9</iyy>
						<izz>2100e-9</izz>
						<ixy>0</ixy>
						<ixz>0</ixz>
						<iyz>0</iyz>
					</inertia>
				</inertial>
				<collision name="Driver-adapter">
					<geometry>
						<mesh>
							<uri>model://parallelogram_arm_robot/meshes/Driver-adapter.dae</uri>
							<scale>0.001 0.001 0.001 </scale>
						</mesh>
					</geometry>
				</collision>
			
				<visual name="Driver-adapter">
					<geometry>
						<mesh>
							<uri>model://parallelogram_arm_robot/meshes/Driver-adapter.dae</uri>
							<scale>0.001 0.001 0.001 </scale>
						</mesh>					
					</geometry>
					<material>
						<ambient> 0.5 0 0 0 </ambient>
					</material>			
				</visual>
			</link>			

	<!-- ############### joint0 01 ############## -->
			<joint type="revolute" name="jointDD1">
				<pose>0.025 0.025 0.0 0 0 0 </pose>
				<child>Driver1</child>
				<parent>Driver-adapter</parent>			
				<axis>
					<xyz>0 1 0</xyz>
				</axis>
			</joint>					
	<!-- #################################################### -->

	<!-- ############### joint0 01 ############## -->
			<joint type="revolute" name="jointD3l">
				<pose>0.172 0.015 0.0 0 0 0 </pose>
				<child>Link3l</child>
				<parent>Driver1</parent>			
				<axis>
					<xyz>0 1 0</xyz>
				</axis>
			</joint>			
		
	<!-- ############### joint0 01 ############## -->
			<joint type="revolute" name="jointD3r">
				<pose>0.172 0.015 0.0 0 0 0 </pose>
				<child>Link3r</child>
				<parent>Driver1</parent>			
				<axis>
					<xyz>0 1 0</xyz>
				</axis>
			</joint>				
	<!-- ##################################################-->
			<link name="Driver1">
				<pose> 0.025 0.0025 0.0805  1.57 -1.57 0</pose>
				<inertial>
					<pose>0.084 0.027 0.005 0 0 0</pose>
					<mass> 0.043 </mass>
					<inertia>
						<ixx>5656e-9</ixx>
						<iyy>123676e-9</iyy>
						<izz>128604e-9</izz>
						<ixy>448e-9</ixy>
						<ixz>0</ixz>
						<iyz>0</iyz>
					</inertia>
				</inertial>
				<collision name="Driver1">
					<geometry>
						<mesh>
							<uri>model://parallelogram_arm_robot/meshes/Driver1.dae</uri>
							<scale>0.001 0.001 0.001 </scale>
						</mesh>
					</geometry>
				</collision>
			
				<visual name="Driver1">
					<geometry>
						<mesh>
							<uri>model://parallelogram_arm_robot/meshes/Driver1.dae</uri>
							<scale>0.001 0.001 0.001 </scale>
						</mesh>					
					</geometry>
					<material>
						<ambient> 0.1 0.6 0 0.5 </ambient>
					</material>			
				</visual>
			</link>
		
	<!-- ############### joint0 01 ############## -->
			<joint type="revolute" name="jointDD2">
				<pose>0.069 0.025 0.0 0 0 0 </pose>
				<child>Driver2</child>
				<parent>Driver-adapter2</parent>			
				<axis>
					<xyz>0 1 0</xyz>
				</axis>
			</joint>					

	<!-- ##################################################-->
			<link name="Driver2">
				<pose> 0.07 0.01 0.1305  1.57 3.14 0</pose>
				<inertial>
					<pose>0.051 0.025 0.002 0 0 0</pose>
					<mass> 0.011 </mass>
					<inertia>
						<ixx>1526e-9</ixx>
						<iyy>7091e-9</iyy>
						<izz>8575e-9</izz>
						<ixy>0</ixy>
						<ixz>0</ixz>
						<iyz>0</iyz>
					</inertia>
				</inertial>
				<collision name="Driver2">
					<geometry>
						<mesh>
							<uri>model://parallelogram_arm_robot/meshes/Driver2.dae</uri>
							<scale>0.001 0.001 0.001 </scale>
						</mesh>
					</geometry>
				</collision>
			
				<visual name="Driver2">
					<geometry>
						<mesh>
							<uri>model://parallelogram_arm_robot/meshes/Driver2.dae</uri>
							<scale>0.001 0.001 0.001 </scale>
						</mesh>					
					</geometry>
					<material>
						<ambient> 0.9 0.9 0.1 0.5 </ambient>
					</material>			
				</visual>
			</link>
		
	<!-- ##################################################-->
			<link name="Driver-adapter2">
				<pose> -0.025 0.015 0.0805  1.57 0 0</pose>
				<inertial>
					<pose>0.025 0.025 0.002 0 0 0</pose>
					<mass> 0.006 </mass>
					<inertia>
						<ixx>1064e-9</ixx>
						<iyy>1064e-9</iyy>
						<izz>2100e-9</izz>
						<ixy>0</ixy>
						<ixz>0</ixz>
						<iyz>0</iyz>
					</inertia>
				</inertial>
				<collision name="Driver-adapter2">
					<geometry>
						<mesh>
							<uri>model://parallelogram_arm_robot/meshes/Driver-adapter.dae</uri>
							<scale>0.001 0.001 0.001 </scale>
						</mesh>
					</geometry>
				</collision>
			
				<visual name="Driver-adapter2">
					<geometry>
						<mesh>
							<uri>model://parallelogram_arm_robot/meshes/Driver-adapter.dae</uri>
							<scale>0.001 0.001 0.001 </scale>
						</mesh>					
					</geometry>
					<material>
						<ambient> 0.5 0 0 0 </ambient>
					</material>			
				</visual>
			</link>			

	<!-- ############### joint0 01 ############## -->
			<joint type="revolute" name="jointD26">
				<pose>0.015 0.015 0.0 0 0 0 </pose>
				<child>Link6</child>
				<parent>Driver2</parent>			
				<axis>
					<xyz>0 1 0</xyz>
				</axis>
			</joint>			
	<!-- ##################################################-->
			<link name="Link6">
				<pose> 0.07 0.003 0.0905  -1.57 -1.57 3.14</pose>
				<inertial>
					<pose>0.095 0.014 0.002 0 0 0</pose>
					<mass> 0.01 </mass>
					<inertia>
						<ixx>411455100e-15</ixx>
						<ixy>1844.5e-15</ixy>
						<ixz>357e-15</ixz>
						<iyy>37958830000e-15</iyy>
						<iyz>-4.2e-15</iyz>
						<izz>38327074800e-15</izz>
					</inertia>
				</inertial>
				<collision name="Link6">
					<geometry>
						<mesh>
							<uri>model://parallelogram_arm_robot/meshes/Link6.dae</uri>
							<scale>0.001 0.001 0.001 </scale>
						</mesh>
					</geometry>
				</collision>
			
				<visual name="Link6">
					<geometry>
						<mesh>
							<uri>model://parallelogram_arm_robot/meshes/Link6.dae</uri>
							<scale>0.001 0.001 0.001 </scale>
						</mesh>					
					</geometry>
					<material>
						<ambient> 0.5 0 0 0 </ambient>
					</material>			
				</visual>
			</link>	

	<!-- ############### joint0 01 ############## -->
			<joint type="revolute" name="joint63r">
				<pose>0.225 0.0155 0.0 0 0 0 </pose>
				<child>Link3r</child>
				<parent>Link6</parent>			
				<axis>
					<xyz>0 1 0</xyz>
				</axis>
			</joint>		
	<!-- ##################################################-->
			<link name="Link3r">
				<pose> -0.1625 0.008 0.205  -1.57 3.34 3.14</pose>
				<inertial>
					<pose>0.132 0.016 0.002 0 0 0</pose>
					<mass> 0.015 </mass>
					<inertia>
						<ixx>686e-9</ixx>
						<iyy>69720e-9</iyy>
						<izz>70349e-9</izz>
						<ixy>-444e-9</ixy>
						<ixz>0</ixz>
						<iyz>0</iyz>
					</inertia>
				</inertial>
				<collision name="Link3r">
					<geometry>
						<mesh>
							<uri>model://parallelogram_arm_robot/meshes/Link3.dae</uri>
							<scale>0.001 0.001 0.001 </scale>
						</mesh>
					</geometry>
				</collision>
			
				<visual name="Link3r">
					<geometry>
						<mesh>
							<uri>model://parallelogram_arm_robot/meshes/Link3.dae</uri>
							<scale>0.001 0.001 0.001 </scale>
						</mesh>					
					</geometry>
					<material>
						<ambient> 0 0.5 0.5 0 </ambient>
					</material>			
				</visual>
			</link>

	<!-- ############### joint0 01 ############## -->
			<joint type="revolute" name="joint63l">
				<pose>0.225 0.0155 0.0 0 0 0 </pose>
				<child>Link3l</child>
				<parent>Link6</parent>			
				<axis>
					<xyz>0 1 0</xyz>
				</axis>
			</joint>			
	<!-- ##################################################-->
			<link name="Link3l">
				<pose> -0.1625 -0.009 0.205  -1.57 3.34 3.14</pose>
				<inertial>
					<pose>0.132 0.016 0.002 0 0 0</pose>
					<mass> 0.015 </mass>
					<inertia>
						<ixx>686e-9</ixx>
						<iyy>69720e-9</iyy>
						<izz>70349e-9</izz>
						<ixy>-444e-9</ixy>
						<ixz>0</ixz>
						<iyz>0</iyz>
					</inertia>
				</inertial>
				<collision name="Link3l">
					<geometry>
						<mesh>
							<uri>model://parallelogram_arm_robot/meshes/Link3.dae</uri>
							<scale>0.001 0.001 0.001 </scale>
						</mesh>
					</geometry>
				</collision>
			
				<visual name="Link3l">
					<geometry>
						<mesh>
							<uri>model://parallelogram_arm_robot/meshes/Link3.dae</uri>
							<scale>0.001 0.001 0.001 </scale>
						</mesh>					
					</geometry>
					<material>
						<ambient> 0 0.5 0.5 0 </ambient>
					</material>			
				</visual>
			</link>	
		
	<!-- ##################################################-->
			<link name="x-link5">
				<pose> -0.200 -0.014 0.206  1.57 0 0</pose>
				<inertial>
					<pose>0.021 0.017 0.002 0 0 0</pose>
					<mass> 0.004 </mass>
					<inertia>
						<ixx>623e-9</ixx>
						<iyy>938e-9</iyy>
						<izz>1540e-9</izz>
						<ixy>336e-9</ixy>
						<ixz>0</ixz>
						<iyz>0</iyz>
					</inertia>
				</inertial>
				<collision name="x-link5">
					<geometry>
						<mesh>
							<uri>model://parallelogram_arm_robot/meshes/x-link5.dae</uri>
							<scale>0.001 0.001 0.001 </scale>
						</mesh>
					</geometry>
				</collision>
			
				<visual name="x-link5">
					<geometry>
						<mesh>
							<uri>model://parallelogram_arm_robot/meshes/x-link5.dae</uri>
							<scale>0.001 0.001 0.001 </scale>
						</mesh>					
					</geometry>
					<material>
						<ambient> 0 0 0.5 0.5 </ambient>
					</material>			
				</visual>
			</link>

	<!-- ############### joint0 01 ############## -->
			<joint type="revolute" name="joint3lx">
				<pose>0.045 0.01 0.0 0 0 0 </pose>
				<child>x-link5</child>
				<parent>Link3l</parent>			
				<axis>
					<xyz>0 1 0</xyz>
					<limit>
						<upper> 0 </upper>
						<lower> 0 </lower>
					</limit>				
				</axis>
			</joint>	
	<!-- ##################################################-->
			<link name="x-link5-counter">
				<pose> -0.200 0.014 0.206  1.57 0 0</pose>
				<inertial>
					<pose>0.026 0.009 0.002 0 0 0</pose>
					<mass> 0.0026 </mass>
					<inertia>
						<ixx>623e-9</ixx>
						<iyy>938e-9</iyy>
						<izz>1540e-9</izz>
						<ixy>336e-9</ixy>
						<ixz>0</ixz>
						<iyz>0</iyz>
					</inertia>
				</inertial>
				<collision name="x-link5-counter">
					<geometry>
						<mesh>
							<uri>model://parallelogram_arm_robot/meshes/x-link5-counter.dae</uri>
							<scale>0.001 0.001 0.001 </scale>
						</mesh>
					</geometry>
				</collision>
			
				<visual name="x-link5-counter">
					<geometry>
						<mesh>
							<uri>model://parallelogram_arm_robot/meshes/x-link5-counter.dae</uri>
							<scale>0.001 0.001 0.001 </scale>
						</mesh>					
					</geometry>
					<material>
						<ambient> 0 0 0.5 0.5 </ambient>
					</material>			
				</visual>
			</link>
		
	<!-- ############### joint0 01 ############## -->
			<joint type="revolute" name="joint3rx">
				<pose>0.045 0.01 0.0 0 0 0 </pose>
				<child>x-link5-counter</child>
				<parent>Link3r</parent>			
				<axis>
					<xyz>0 1 0</xyz>
					<limit>
						<upper> 0 </upper>
						<lower> 0 </lower>
					</limit>			
				</axis>
			</joint>																
			
	<!-- #################### link6  ############## ->

		
			<link name="link6">
				<pose> -0.03 0 0.15 0 0 0 </pose>
				<collision name="collision6">
					<geometry>
						<box>
							<size>0.02 0.03 0.15</size>
						</box>
					</geometry>
				</collision>
			
				<visual name="visual6">
					<geometry>
						<box>
							<size>0.02 0.03 0.15</size>
						</box>
					</geometry>		
				</visual>
				<inertial>
					<mass> 1 </mass>
					<inertia>
						<ixx>0.0019</ixx>
						<iyy>0.00195</iyy>
						<izz>0.00010</izz>
						<ixy>0</ixy>
						<ixz>0</ixz>
						<iyz>0</iyz>
					</inertia>
				</inertial>			
			</link-->	
			<!-- Attach the plugin to this model -->			
			<plugin name="arm_control" filename="libarm_plugin.so">
				<velocity>0.0</velocity>
				<velocity12>0.01</velocity12>
			</plugin>
		</model>
	</world>
</sdf>
